Traceback (most recent call last):
  File "/home/lohith/miniconda3/envs/ioos/lib/python3.6/site-packages/jupyter_cache/executors/utils.py", line 56, in single_nb_execution
    record_timing=False,
  File "/home/lohith/miniconda3/envs/ioos/lib/python3.6/site-packages/nbclient/client.py", line 1112, in execute
    return NotebookClient(nb=nb, resources=resources, km=km, **kwargs).execute()
  File "/home/lohith/miniconda3/envs/ioos/lib/python3.6/site-packages/nbclient/util.py", line 74, in wrapped
    return just_run(coro(*args, **kwargs))
  File "/home/lohith/miniconda3/envs/ioos/lib/python3.6/site-packages/nbclient/util.py", line 53, in just_run
    return loop.run_until_complete(coro)
  File "/home/lohith/miniconda3/envs/ioos/lib/python3.6/asyncio/base_events.py", line 488, in run_until_complete
    return future.result()
  File "/home/lohith/miniconda3/envs/ioos/lib/python3.6/site-packages/nbclient/client.py", line 554, in async_execute
    cell, index, execution_count=self.code_cells_executed + 1
  File "/home/lohith/miniconda3/envs/ioos/lib/python3.6/site-packages/nbclient/client.py", line 857, in async_execute_cell
    self._check_raise_for_error(cell, exec_reply)
  File "/home/lohith/miniconda3/envs/ioos/lib/python3.6/site-packages/nbclient/client.py", line 760, in _check_raise_for_error
    raise CellExecutionError.from_cell_and_msg(cell, exec_reply_content)
nbclient.exceptions.CellExecutionError: An error occurred while executing the following cell:
------------------
import os
import shutil
from datetime import datetime

from ioos_tools.ioos import parse_config

config = parse_config("config.yaml")

# Saves downloaded data into a temporary directory.
save_dir = os.path.abspath(config["run_name"])
if os.path.exists(save_dir):
    shutil.rmtree(save_dir)
os.makedirs(save_dir)

fmt = "{:*^64}".format
print(fmt("Saving data inside directory {}".format(save_dir)))
print(fmt(" Run information "))
print("Run date: {:%Y-%m-%d %H:%M:%S}".format(datetime.utcnow()))
print("Start: {:%Y-%m-%d %H:%M:%S}".format(config["date"]["start"]))
print("Stop: {:%Y-%m-%d %H:%M:%S}".format(config["date"]["stop"]))
print(
    "Bounding box: {0:3.2f}, {1:3.2f},"
    "{2:3.2f}, {3:3.2f}".format(*config["region"]["bbox"])
)
------------------

[0;31m---------------------------------------------------------------------------[0m
[0;31mModuleNotFoundError[0m                       Traceback (most recent call last)
[0;32m<ipython-input-3-9cb6d344ebc5>[0m in [0;36m<module>[0;34m[0m
[1;32m      3[0m [0;32mfrom[0m [0mdatetime[0m [0;32mimport[0m [0mdatetime[0m[0;34m[0m[0;34m[0m[0m
[1;32m      4[0m [0;34m[0m[0m
[0;32m----> 5[0;31m [0;32mfrom[0m [0mioos_tools[0m[0;34m.[0m[0mioos[0m [0;32mimport[0m [0mparse_config[0m[0;34m[0m[0;34m[0m[0m
[0m[1;32m      6[0m [0;34m[0m[0m
[1;32m      7[0m [0mconfig[0m [0;34m=[0m [0mparse_config[0m[0;34m([0m[0;34m"config.yaml"[0m[0;34m)[0m[0;34m[0m[0;34m[0m[0m

[0;31mModuleNotFoundError[0m: No module named 'ioos_tools'
ModuleNotFoundError: No module named 'ioos_tools'

