Traceback (most recent call last):
  File "/home/lohith/miniconda3/envs/ioos/lib/python3.6/site-packages/jupyter_cache/executors/utils.py", line 56, in single_nb_execution
    record_timing=False,
  File "/home/lohith/miniconda3/envs/ioos/lib/python3.6/site-packages/nbclient/client.py", line 1112, in execute
    return NotebookClient(nb=nb, resources=resources, km=km, **kwargs).execute()
  File "/home/lohith/miniconda3/envs/ioos/lib/python3.6/site-packages/nbclient/util.py", line 74, in wrapped
    return just_run(coro(*args, **kwargs))
  File "/home/lohith/miniconda3/envs/ioos/lib/python3.6/site-packages/nbclient/util.py", line 53, in just_run
    return loop.run_until_complete(coro)
  File "/home/lohith/miniconda3/envs/ioos/lib/python3.6/asyncio/base_events.py", line 488, in run_until_complete
    return future.result()
  File "/home/lohith/miniconda3/envs/ioos/lib/python3.6/site-packages/nbclient/client.py", line 554, in async_execute
    cell, index, execution_count=self.code_cells_executed + 1
  File "/home/lohith/miniconda3/envs/ioos/lib/python3.6/site-packages/nbclient/client.py", line 857, in async_execute_cell
    self._check_raise_for_error(cell, exec_reply)
  File "/home/lohith/miniconda3/envs/ioos/lib/python3.6/site-packages/nbclient/client.py", line 760, in _check_raise_for_error
    raise CellExecutionError.from_cell_and_msg(cell, exec_reply_content)
nbclient.exceptions.CellExecutionError: An error occurred while executing the following cell:
------------------
from glob import glob

import geopandas

cones, points = [], []
for fname in sorted(glob(os.path.join(base, "{}_*.zip".format(hurricane)))):
    number = os.path.splitext(os.path.split(fname)[-1])[0].split("_")[-1]
    pgn = geopandas.read_file(
        "/{}-{}_5day_pgn.shp".format(code, number), vfs="zip://{}".format(fname)
    )
    cones.append(pgn)

    pts = geopandas.read_file(
        "/{}-{}_5day_pts.shp".format(code, number), vfs="zip://{}".format(fname)
    )
    # Only the first "obsevartion."
    points.append(pts.iloc[0])
------------------

[0;31m---------------------------------------------------------------------------[0m
[0;31mModuleNotFoundError[0m                       Traceback (most recent call last)
[0;32m<ipython-input-6-1862985ee59d>[0m in [0;36m<module>[0;34m[0m
[1;32m      1[0m [0;32mfrom[0m [0mglob[0m [0;32mimport[0m [0mglob[0m[0;34m[0m[0;34m[0m[0m
[1;32m      2[0m [0;34m[0m[0m
[0;32m----> 3[0;31m [0;32mimport[0m [0mgeopandas[0m[0;34m[0m[0;34m[0m[0m
[0m[1;32m      4[0m [0;34m[0m[0m
[1;32m      5[0m [0mcones[0m[0;34m,[0m [0mpoints[0m [0;34m=[0m [0;34m[[0m[0;34m][0m[0;34m,[0m [0;34m[[0m[0;34m][0m[0;34m[0m[0;34m[0m[0m

[0;31mModuleNotFoundError[0m: No module named 'geopandas'
ModuleNotFoundError: No module named 'geopandas'

