Traceback (most recent call last):
  File "/home/lohith/miniconda3/envs/IOOS/lib/python3.9/site-packages/jupyter_cache/executors/utils.py", line 51, in single_nb_execution
    executenb(
  File "/home/lohith/miniconda3/envs/IOOS/lib/python3.9/site-packages/nbclient/client.py", line 1112, in execute
    return NotebookClient(nb=nb, resources=resources, km=km, **kwargs).execute()
  File "/home/lohith/miniconda3/envs/IOOS/lib/python3.9/site-packages/nbclient/util.py", line 74, in wrapped
    return just_run(coro(*args, **kwargs))
  File "/home/lohith/miniconda3/envs/IOOS/lib/python3.9/site-packages/nbclient/util.py", line 53, in just_run
    return loop.run_until_complete(coro)
  File "/home/lohith/miniconda3/envs/IOOS/lib/python3.9/asyncio/base_events.py", line 642, in run_until_complete
    return future.result()
  File "/home/lohith/miniconda3/envs/IOOS/lib/python3.9/site-packages/nbclient/client.py", line 553, in async_execute
    await self.async_execute_cell(
  File "/home/lohith/miniconda3/envs/IOOS/lib/python3.9/site-packages/nbclient/client.py", line 857, in async_execute_cell
    self._check_raise_for_error(cell, exec_reply)
  File "/home/lohith/miniconda3/envs/IOOS/lib/python3.9/site-packages/nbclient/client.py", line 760, in _check_raise_for_error
    raise CellExecutionError.from_cell_and_msg(cell, exec_reply_content)
nbclient.exceptions.CellExecutionError: An error occurred while executing the following cell:
------------------
import pandas as pd

from rpy2.robjects import pandas2ri

pandas2ri.activate()
df = pandas2ri.ri2py_dataframe(rdf)

cols = ["longitude", "latitude", "depth", "quantificationValue"]
df[cols] = df[cols].apply(pd.to_numeric)

df.head()
------------------

[0;31m---------------------------------------------------------------------------[0m
[0;31mAttributeError[0m                            Traceback (most recent call last)
[0;32m<ipython-input-4-2cf9e55ef1b8>[0m in [0;36m<module>[0;34m[0m
[1;32m      4[0m [0;34m[0m[0m
[1;32m      5[0m [0mpandas2ri[0m[0;34m.[0m[0mactivate[0m[0;34m([0m[0;34m)[0m[0;34m[0m[0;34m[0m[0m
[0;32m----> 6[0;31m [0mdf[0m [0;34m=[0m [0mpandas2ri[0m[0;34m.[0m[0mri2py_dataframe[0m[0;34m([0m[0mrdf[0m[0;34m)[0m[0;34m[0m[0;34m[0m[0m
[0m[1;32m      7[0m [0;34m[0m[0m
[1;32m      8[0m [0mcols[0m [0;34m=[0m [0;34m[[0m[0;34m"longitude"[0m[0;34m,[0m [0;34m"latitude"[0m[0;34m,[0m [0;34m"depth"[0m[0;34m,[0m [0;34m"quantificationValue"[0m[0;34m][0m[0;34m[0m[0;34m[0m[0m

[0;31mAttributeError[0m: module 'rpy2.robjects.pandas2ri' has no attribute 'ri2py_dataframe'
AttributeError: module 'rpy2.robjects.pandas2ri' has no attribute 'ri2py_dataframe'

