Traceback (most recent call last):
  File "/home/lohith/miniconda3/envs/ioos/lib/python3.6/site-packages/jupyter_cache/executors/utils.py", line 56, in single_nb_execution
    record_timing=False,
  File "/home/lohith/miniconda3/envs/ioos/lib/python3.6/site-packages/nbclient/client.py", line 1112, in execute
    return NotebookClient(nb=nb, resources=resources, km=km, **kwargs).execute()
  File "/home/lohith/miniconda3/envs/ioos/lib/python3.6/site-packages/nbclient/util.py", line 74, in wrapped
    return just_run(coro(*args, **kwargs))
  File "/home/lohith/miniconda3/envs/ioos/lib/python3.6/site-packages/nbclient/util.py", line 53, in just_run
    return loop.run_until_complete(coro)
  File "/home/lohith/miniconda3/envs/ioos/lib/python3.6/asyncio/base_events.py", line 488, in run_until_complete
    return future.result()
  File "/home/lohith/miniconda3/envs/ioos/lib/python3.6/site-packages/nbclient/client.py", line 554, in async_execute
    cell, index, execution_count=self.code_cells_executed + 1
  File "/home/lohith/miniconda3/envs/ioos/lib/python3.6/site-packages/nbclient/client.py", line 857, in async_execute_cell
    self._check_raise_for_error(cell, exec_reply)
  File "/home/lohith/miniconda3/envs/ioos/lib/python3.6/site-packages/nbclient/client.py", line 760, in _check_raise_for_error
    raise CellExecutionError.from_cell_and_msg(cell, exec_reply_content)
nbclient.exceptions.CellExecutionError: An error occurred while executing the following cell:
------------------
%matplotlib inline


import matplotlib.pyplot as plt
from oceans.plotting import stick_plot

q = stick_plot([t.to_pydatetime() for t in df["time"]], df["u"], df["v"])

ref = 1
qk = plt.quiverkey(
    q, 0.1, 0.85, ref, f"{ref} m s$^{-1}$", labelpos="N", coordinates="axes"
)

plt.xticks(rotation=70)
------------------

[0;31m---------------------------------------------------------------------------[0m
[0;31mModuleNotFoundError[0m                       Traceback (most recent call last)
[0;32m<ipython-input-2-bf294b69a925>[0m in [0;36m<module>[0;34m[0m
[1;32m      3[0m [0;34m[0m[0m
[1;32m      4[0m [0;32mimport[0m [0mmatplotlib[0m[0;34m.[0m[0mpyplot[0m [0;32mas[0m [0mplt[0m[0;34m[0m[0;34m[0m[0m
[0;32m----> 5[0;31m [0;32mfrom[0m [0moceans[0m[0;34m.[0m[0mplotting[0m [0;32mimport[0m [0mstick_plot[0m[0;34m[0m[0;34m[0m[0m
[0m[1;32m      6[0m [0;34m[0m[0m
[1;32m      7[0m [0mq[0m [0;34m=[0m [0mstick_plot[0m[0;34m([0m[0;34m[[0m[0mt[0m[0;34m.[0m[0mto_pydatetime[0m[0;34m([0m[0;34m)[0m [0;32mfor[0m [0mt[0m [0;32min[0m [0mdf[0m[0;34m[[0m[0;34m"time"[0m[0;34m][0m[0;34m][0m[0;34m,[0m [0mdf[0m[0;34m[[0m[0;34m"u"[0m[0;34m][0m[0;34m,[0m [0mdf[0m[0;34m[[0m[0;34m"v"[0m[0;34m][0m[0;34m)[0m[0;34m[0m[0;34m[0m[0m

[0;31mModuleNotFoundError[0m: No module named 'oceans'
ModuleNotFoundError: No module named 'oceans'

