Traceback (most recent call last):
  File "/home/lohith/miniconda3/envs/ioos/lib/python3.6/site-packages/jupyter_cache/executors/utils.py", line 56, in single_nb_execution
    record_timing=False,
  File "/home/lohith/miniconda3/envs/ioos/lib/python3.6/site-packages/nbclient/client.py", line 1112, in execute
    return NotebookClient(nb=nb, resources=resources, km=km, **kwargs).execute()
  File "/home/lohith/miniconda3/envs/ioos/lib/python3.6/site-packages/nbclient/util.py", line 74, in wrapped
    return just_run(coro(*args, **kwargs))
  File "/home/lohith/miniconda3/envs/ioos/lib/python3.6/site-packages/nbclient/util.py", line 53, in just_run
    return loop.run_until_complete(coro)
  File "/home/lohith/miniconda3/envs/ioos/lib/python3.6/asyncio/base_events.py", line 488, in run_until_complete
    return future.result()
  File "/home/lohith/miniconda3/envs/ioos/lib/python3.6/site-packages/nbclient/client.py", line 554, in async_execute
    cell, index, execution_count=self.code_cells_executed + 1
  File "/home/lohith/miniconda3/envs/ioos/lib/python3.6/site-packages/nbclient/client.py", line 857, in async_execute_cell
    self._check_raise_for_error(cell, exec_reply)
  File "/home/lohith/miniconda3/envs/ioos/lib/python3.6/site-packages/nbclient/client.py", line 760, in _check_raise_for_error
    raise CellExecutionError.from_cell_and_msg(cell, exec_reply_content)
nbclient.exceptions.CellExecutionError: An error occurred while executing the following cell:
------------------
from gridgeo import GridGeo
from netCDF4 import Dataset

for model, value in list(models.items()):
    try:
        nc = Dataset(value["url"])
    except Exception:
        print(f'Could not download {value["url"]}')
        models.pop(model)
        continue
    models[model].update({"nc": nc})
    models[model].update({"grid": GridGeo(nc, **value["var"])})
------------------

[0;31m---------------------------------------------------------------------------[0m
[0;31mModuleNotFoundError[0m                       Traceback (most recent call last)
[0;32m<ipython-input-2-a3e145b30c26>[0m in [0;36m<module>[0;34m[0m
[0;32m----> 1[0;31m [0;32mfrom[0m [0mgridgeo[0m [0;32mimport[0m [0mGridGeo[0m[0;34m[0m[0;34m[0m[0m
[0m[1;32m      2[0m [0;32mfrom[0m [0mnetCDF4[0m [0;32mimport[0m [0mDataset[0m[0;34m[0m[0;34m[0m[0m
[1;32m      3[0m [0;34m[0m[0m
[1;32m      4[0m [0;32mfor[0m [0mmodel[0m[0;34m,[0m [0mvalue[0m [0;32min[0m [0mlist[0m[0;34m([0m[0mmodels[0m[0;34m.[0m[0mitems[0m[0;34m([0m[0;34m)[0m[0;34m)[0m[0;34m:[0m[0;34m[0m[0;34m[0m[0m
[1;32m      5[0m     [0;32mtry[0m[0;34m:[0m[0;34m[0m[0;34m[0m[0m

[0;31mModuleNotFoundError[0m: No module named 'gridgeo'
ModuleNotFoundError: No module named 'gridgeo'

