Traceback (most recent call last):
  File "/home/lohith/miniconda3/envs/ioos/lib/python3.6/site-packages/jupyter_cache/executors/utils.py", line 56, in single_nb_execution
    record_timing=False,
  File "/home/lohith/miniconda3/envs/ioos/lib/python3.6/site-packages/nbclient/client.py", line 1112, in execute
    return NotebookClient(nb=nb, resources=resources, km=km, **kwargs).execute()
  File "/home/lohith/miniconda3/envs/ioos/lib/python3.6/site-packages/nbclient/util.py", line 74, in wrapped
    return just_run(coro(*args, **kwargs))
  File "/home/lohith/miniconda3/envs/ioos/lib/python3.6/site-packages/nbclient/util.py", line 53, in just_run
    return loop.run_until_complete(coro)
  File "/home/lohith/miniconda3/envs/ioos/lib/python3.6/asyncio/base_events.py", line 488, in run_until_complete
    return future.result()
  File "/home/lohith/miniconda3/envs/ioos/lib/python3.6/site-packages/nbclient/client.py", line 554, in async_execute
    cell, index, execution_count=self.code_cells_executed + 1
  File "/home/lohith/miniconda3/envs/ioos/lib/python3.6/site-packages/nbclient/client.py", line 857, in async_execute_cell
    self._check_raise_for_error(cell, exec_reply)
  File "/home/lohith/miniconda3/envs/ioos/lib/python3.6/site-packages/nbclient/client.py", line 760, in _check_raise_for_error
    raise CellExecutionError.from_cell_and_msg(cell, exec_reply_content)
nbclient.exceptions.CellExecutionError: An error occurred while executing the following cell:
------------------
import os
from pathlib import Path

import geopandas
import pandas as pd


def load_best_track(code="al14", year="2018"):
    fname = Path(f"{code}{year}_best_track.zip")

    if not fname.is_file():
        import urllib.request

        url = f"https://www.nhc.noaa.gov/gis/best_track/{fname}"
        urllib.request.urlretrieve(url, fname)

    os.environ["CPL_ZIP_ENCODING"] = "UTF-8"

    radii = geopandas.read_file(
        f"/{code.upper()}{year}_radii.shp", vfs=f"zip://{fname}"
    )

    pts = geopandas.read_file(f"/{code.upper()}{year}_pts.shp", vfs=f"zip://{fname}")

    pts["str"] = pts["DTG"].astype(int).astype(str)

    pts.index = pd.to_datetime(pts["str"], format="%Y%m%d%H", errors="coerce").values

    radii.index = pd.to_datetime(
        radii["SYNOPTIME"], format="%Y%m%d%H", errors="coerce"
    ).values
    return radii, pts
------------------

[0;31m---------------------------------------------------------------------------[0m
[0;31mModuleNotFoundError[0m                       Traceback (most recent call last)
[0;32m<ipython-input-1-9ec8b9c8f575>[0m in [0;36m<module>[0;34m[0m
[1;32m      2[0m [0;32mfrom[0m [0mpathlib[0m [0;32mimport[0m [0mPath[0m[0;34m[0m[0;34m[0m[0m
[1;32m      3[0m [0;34m[0m[0m
[0;32m----> 4[0;31m [0;32mimport[0m [0mgeopandas[0m[0;34m[0m[0;34m[0m[0m
[0m[1;32m      5[0m [0;32mimport[0m [0mpandas[0m [0;32mas[0m [0mpd[0m[0;34m[0m[0;34m[0m[0m
[1;32m      6[0m [0;34m[0m[0m

[0;31mModuleNotFoundError[0m: No module named 'geopandas'
ModuleNotFoundError: No module named 'geopandas'

